Workbook

Sheet SUPUESTOS
A1: BITAFLY — SUPUESTOS DEL MODELO
A2: Cambia cualquier celda amarilla → todo el modelo se actualiza automáticamente
A4: 1. PRECIOS (COP)
A5: Plan | B5: Mensual | C5: Anual | D5: Equiv. mensual anual | E5: Descuento anual
A6: Piloto | B6: 19900 | C6: 218900 | D6: =C6/12 -> 18241.667 | E6: =1-D6/B6 -> 0.083333333
A7: Escuadrilla | B7: 149900 | C7: 1648900 | D7: =C7/12 -> 137408.33 | E7: =1-D7/B7 -> 0.083333333
A8: Flota | B8: 249900 | C8: 2748900 | D8: =C8/12 -> 229075 | E8: =1-D8/B8 -> 0.083333333
A9: Enterprise | B9: 0 | C9: 5000000 | D9: =C9/12 -> 416666.67 | E9: Variable
A11: 2. MEZCLA DE PLANES (ajustar según tracción real)
A12: Plan | B12: % de clientes | C12: ARPU parcial (COP)
A13: Piloto | B13: 0.6 | C13: =B13*B6 -> 11940
A14: Escuadrilla | B14: 0.25 | C14: =B14*B7 -> 37475
A15: Flota | B15: 0.12 | C15: =B15*B8 -> 29988
A16: Enterprise | B16: 0.03 | C16: =B16*C9 -> 150000
A17: SUMA DE MEZCLA (debe = 100%) | B17: =SUM(B13:B16) -> 1
A18: ★ ARPU MENSUAL MEZCLADO (COP) | B18: =SUM(C13:C16) -> 229403
A20: 3. EMBUDO Y RETENCIÓN
A21: Variable | B21: Valor | C21: Notas
A22: CPC Google Colombia (COP/clic) | B22: 2500 | C22: Costo por clic en Google Ads
A23: Conversión landing → prueba (%) | B23: 0.07 | C23: Tasa de registro a prueba gratuita
A24: Conversión prueba → pago (%) | B24: 0.08 | C24: Tasa de conversión a cliente de pago
A25: Churn mensual (%) | B25: 0.04 | C25: Cancelaciones por mes (meta <5%)
A26: Margen bruto (%) | B26: 0.85 | C26: Ingresos – costos directos por cliente
A27: CAC (COP / cliente) | B27: 400000 | C27: Costo total por cliente adquirido
A28: Vida media del cliente (meses = 1/churn) | B28: =1/B25 -> 25
A29: LTV (COP) = ARPU × Margen × Vida media | B29: =B18*B26*B28 -> 4874813.8
A30: LTV / CAC | B30: =B29/B27 -> 12.187034
A31: Payback de CAC (meses) | B31: =B27/(B18*B26) -> 2.0513604
A33: 4. COSTOS FIJOS MENSUALES (COP)
A34: Concepto | B34: COP/mes | C34: USD/mes | D34: Notas
A35: TRM (COP/USD) | B35: 3800 | D35: Tasa de cambio referencia
A36: Vercel | B36: =C36*B35 -> 76000 | C36: 20 | D36: Pro plan
A37: Supabase | B37: =C37*B35 -> 76000 | C37: 20 | D37: Pro plan
A38: Resend | B38: =C38*B35 -> 76000 | C38: 20 | D38: Email transaccional
A39: Railway | B39: =C39*B35 -> 76000 | C39: 20 | D39: Workers/cron
A40: Dominio | B40: =(60000/12) -> 5000 | D40: Anual ÷ 12
A41: Email corporativo | B41: =(70800/12) -> 5900 | D41: G-Suite o similar
A42: ePayco (cuota fija) | B42: 73400 | D42: Flat ≤$5M COP/mes
A43: Siigo (facturación) | B43: 12417 | D43: $149.000/año ÷ 12
A44: Cámara y Comercio | B44: 8333 | D44: $100.000/año ÷ 12
...

Sheet Hoja1

Sheet AÑO 1
A1: BITAFLY — PROYECCIÓN AÑO 1 (Mes a Mes)
A2: ← Los valores en amarillo se toman de la hoja SUPUESTOS. Cambia los supuestos allá para actualizar todo.
B4: Mes | C4: Nuevos clientes | D4: Clientes activos | E4: MRR (COP) | F4: Marketing (COP) | G4: Equipo (COP) | H4: Costos fijos (COP) | I4: Costo total (COP) | J4: EBITDA mes (COP)
A5: Mes 1 | B5: 1 | C5: =ROUND((SUPUESTOS!B50+(1-1)*SUPUESTOS!B51)*SUPUESTOS!B35/SUPUESTOS!B27,0) -> 4 | D5: =C5 -> 4 | E5: =D5*SUPUESTOS!B18 -> 917612 | F5: =(SUPUESTOS!B50+(1-1)*SUPUESTOS!B51)*SUPUESTOS!B35 -> 1520000 | G5: =IF(1>=SUPUESTOS!B52,SUPUESTOS!B53,0) -> 0 | H5: =SUPUESTOS!B46+IF(E5>SUPUESTOS!B55,(E5-SUPUESTOS!B55)*SUPUESTOS!B54,0) -> 425717 | I5: =F5+G5+H5 -> 1945717 | J5: =E5-I5 -> -1028105
A6: Mes 2 | B6: 2 | C6: =ROUND((SUPUESTOS!B50+(2-1)*SUPUESTOS!B51)*SUPUESTOS!B35/SUPUESTOS!B27,0) -> 5 | D6: =ROUND(D5*(1-SUPUESTOS!B25)+C6,0) -> 9 | E6: =D6*SUPUESTOS!B18 -> 2064627 | F6: =(SUPUESTOS!B50+(2-1)*SUPUESTOS!B51)*SUPUESTOS!B35 -> 1900000 | G6: =IF(2>=SUPUESTOS!B52,SUPUESTOS!B53,0) -> 0 | H6: =SUPUESTOS!B46+IF(E6>SUPUESTOS!B55,(E6-SUPUESTOS!B55)*SUPUESTOS!B54,0) -> 425717 | I6: =F6+G6+H6 -> 2325717 | J6: =E6-I6 -> -261090
A7: Mes 3 | B7: 3 | C7: =ROUND((SUPUESTOS!B50+(3-1)*SUPUESTOS!B51)*SUPUESTOS!B35/SUPUESTOS!B27,0) -> 6 | D7: =ROUND(D6*(1-SUPUESTOS!B25)+C7,0) -> 15 | E7: =D7*SUPUESTOS!B18 -> 3441045 | F7: =(SUPUESTOS!B50+(3-1)*SUPUESTOS!B51)*SUPUESTOS!B35 -> 2280000 | G7: =IF(3>=SUPUESTOS!B52,SUPUESTOS!B53,0) -> 0 | H7: =SUPUESTOS!B46+IF(E7>SUPUESTOS!B55,(E7-SUPUESTOS!B55)*SUPUESTOS!B54,0) -> 425717 | I7: =F7+G7+H7 -> 2705717 | J7: =E7-I7 -> 735328
A8: Mes 4 | B8: 4 | C8: =ROUND((SUPUESTOS!B50+(4-1)*SUPUESTOS!B51)*SUPUESTOS!B35/SUPUESTOS!B27,0) -> 7 | D8: =ROUND(D7*(1-SUPUESTOS!B25)+C8,0) -> 21 | E8: =D8*SUPUESTOS!B18 -> 4817463 | F8: =(SUPUESTOS!B50+(4-1)*SUPUESTOS!B51)*SUPUESTOS!B35 -> 2660000 | G8: =IF(4>=SUPUESTOS!B52,SUPUESTOS!B53,0) -> 0 | H8: =SUPUESTOS!B46+IF(E8>SUPUESTOS!B55,(E8-SUPUESTOS!B55)*SUPUESTOS!B54,0) -> 425717 | I8: =F8+G8+H8 -> 3085717 | J8: =E8-I8 -> 1731746
A9: Mes 5 | B9: 5 | C9: =ROUND((SUPUESTOS!B50+(5-1)*SUPUESTOS!B51)*SUPUESTOS!B35/SUPUESTOS!B27,0) -> 8 | D9: =ROUND(D8*(1-SUPUESTOS!B25)+C9,0) -> 28 | E9: =D9*SUPUESTOS!B18 -> 6423284 | F9: =(SUPUESTOS!B50+(5-1)*SUPUESTOS!B51)*SUPUESTOS!B35 -> 3040000 | G9: =IF(5>=SUPUESTOS!B52,SUPUESTOS!B53,0) -> 0 | H9: =SUPUESTOS!B46+IF(E9>SUPUESTOS!B55,(E9-SUPUESTOS!B55)*SUPUESTOS!B54,0) -> 435679.99 | I9: =F9+G9+H9 -> 3475680 | J9: =E9-I9 -> 2947604
A10: Mes 6 | B10: 6 | C10: =ROUND((SUPUESTOS!B50+(6-1)*SUPUESTOS!B51)*SUPUESTOS!B35/SUPUESTOS!B27,0) -> 9 | D10: =ROUND(D9*(1-SUPUESTOS!B25)+C10,0) -> 36 | E10: =D10*SUPUESTOS!B18 -> 8258508 | F10: =(SUPUESTOS!B50+(6-1)*SUPUESTOS!B51)*SUPUESTOS!B35 -> 3420000 | G10: =IF(6>=SUPUESTOS!B52,SUPUESTOS!B53,0) -> 0 | H10: =SUPUESTOS!B46+IF(E10>SUPUESTOS!B55,(E10-SUPUESTOS!B55)*SUPUESTOS!B54,0) -> 448526.56 | I10: =F10+G10+H10 -> 3868526.6 | J10: =E10-I10 -> 4389981.4
A11: Mes 7 | B11: 7 | C11: =ROUND((SUPUESTOS!B50+(7-1)*SUPUESTOS!B51)*SUPUESTOS!B35/SUPUESTOS!B27,0) -> 10 | D11: =ROUND(D10*(1-SUPUESTOS!B25)+C11,0) -> 45 | E11: =D11*SUPUESTOS!B18 -> 10323135 | F11: =(SUPUESTOS!B50+(7-1)*SUPUESTOS!B51)*SUPUESTOS!B35 -> 3800000 | G11: =IF(7>=SUPUESTOS!B52,SUPUESTOS!B53,0) -> 3500000 | H11: =SUPUESTOS!B46+IF(E11>SUPUESTOS!B55,(E11-SUPUESTOS!B55)*SUPUESTOS!B54,0) -> 462978.95 | I11: =F11+G11+H11 -> 7762978.9 | J11: =E11-I11 -> 2560156.1
A12: Mes 8 | B12: 8 | C12: =ROUND((SUPUESTOS!B50+(8-1)*SUPUESTOS!B51)*SUPUESTOS!B35/SUPUESTOS!B27,0) -> 10 | D12: =ROUND(D11*(1-SUPUESTOS!B25)+C12,0) -> 53 | E12: =D12*SUPUESTOS!B18 -> 12158359 | F12: =(SUPUESTOS!B50+(8-1)*SUPUESTOS!B51)*SUPUESTOS!B35 -> 4180000 | G12: =IF(8>=SUPUESTOS!B52,SUPUESTOS!B53,0) -> 3500000 | H12: =SUPUESTOS!B46+IF(E12>SUPUESTOS!B55,(E12-SUPUESTOS!B55)*SUPUESTOS!B54,0) -> 475825.51 | I12: =F12+G12+H12 -> 8155825.5 | J12: =E12-I12 -> 4002533.5
A13: Mes 9 | B13: 9 | C13: =ROUND((SUPUESTOS!B50+(9-1)*SUPUESTOS!B51)*SUPUESTOS!B35/SUPUESTOS!B27,0) -> 11 | D13: =ROUND(D12*(1-SUPUESTOS!B25)+C13,0) -> 62 | E13: =D13*SUPUESTOS!B18 -> 14222986 | F13: =(SUPUESTOS!B50+(9-1)*SUPUESTOS!B51)*SUPUESTOS!B35 -> 4560000 | G13: =IF(9>=SUPUESTOS!B52,SUPUESTOS!B53,0) -> 3500000 | H13: =SUPUESTOS!B46+IF(E13>SUPUESTOS!B55,(E13-SUPUESTOS!B55)*SUPUESTOS!B54,0) -> 490277.9 | I13: =F13+G13+H13 -> 8550277.9 | J13: =E13-I13 -> 5672708.1
A14: Mes 10 | B14: 10 | C14: =ROUND((SUPUESTOS!B50+(10-1)*SUPUESTOS!B51)*SUPUESTOS!B35/SUPUESTOS!B27,0) -> 12 | D14: =ROUND(D13*(1-SUPUESTOS!B25)+C14,0) -> 72 | E14: =D14*SUPUESTOS!B18 -> 16517016 | F14: =(SUPUESTOS!B50+(10-1)*SUPUESTOS!B51)*SUPUESTOS!B35 -> 4940000 | G14: =IF(10>=SUPUESTOS!B52,SUPUESTOS!B53,0) -> 3500000 | H14: =SUPUESTOS!B46+IF(E14>SUPUESTOS!B55,(E14-SUPUESTOS!B55)*SUPUESTOS!B54,0) -> 506336.11 | I14: =F14+G14+H14 -> 8946336.1 | J14: =E14-I14 -> 7570679.9
A15: Mes 11 | B15: 11 | C15: =ROUND((SUPUESTOS!B50+(11-1)*SUPUESTOS!B51)*SUPUESTOS!B35/SUPUESTOS!B27,0) -> 13 | D15: =ROUND(D14*(1-SUPUESTOS!B25)+C15,0) -> 82 | E15: =D15*SUPUESTOS!B18 -> 18811046 | F15: =(SUPUESTOS!B50+(11-1)*SUPUESTOS!B51)*SUPUESTOS!B35 -> 5320000 | G15: =IF(11>=SUPUESTOS!B52,SUPUESTOS!B53,0) -> 3500000 | H15: =SUPUESTOS!B46+IF(E15>SUPUESTOS!B55,(E15-SUPUESTOS!B55)*SUPUESTOS!B54,0) -> 522394.32 | I15: =F15+G15+H15 -> 9342394.3 | J15: =E15-I15 -> 9468651.7
A16: Mes 12 | B16: 12 | C16: =ROUND((SUPUESTOS!B50+(12-1)*SUPUESTOS!B51)*SUPUESTOS!B35/SUPUESTOS!B27,0) -> 14 | D16: =ROUND(D15*(1-SUPUESTOS!B25)+C16,0) -> 93 | E16: =D16*SUPUESTOS!B18 -> 21334479 | F16: =(SUPUESTOS!B50+(12-1)*SUPUESTOS!B51)*SUPUESTOS!B35 -> 5700000 | G16: =IF(12>=SUPUESTOS!B52,SUPUESTOS!B53,0) -> 3500000 | H16: =SUPUESTOS!B46+IF(E16>SUPUESTOS!B55,(E16-SUPUESTOS!B55)*SUPUESTOS!B54,0) -> 540058.35 | I16: =F16+G16+H16 -> 9740058.4 | J16: =E16-I16 -> 11594421
A18: TOTALES AÑO 1 | C18: =SUM(C5:C16) -> 109 | E18: =SUM(E5:E16) -> 119289560 | F18: =SUM(F5:F16) -> 43320000 | G18: =SUM(G5:G16) -> 21000000 | H18: =SUM(H5:H16) -> 5584945.7 | I18: =SUM(I5:I16) -> 69904946 | J18: =SUM(J5:J16) -> 49384614
A20: EBITDA ACUMULADO (mes a mes) | B20: =J5 -> -1028105 | C20: =C20+J6 -> -3777000 | D20: =D20+J7 -> -5478000 | E20: =E20+J8 -> -7038000 | F20: =F20+J9 -> -8181000 | G20: =G20+J10 -> -8723000 | H20: =H20+J11 -> -12072000 | I20: =I20+J12 -> -14452000 | J20: =J20+J13 -> -15588000 | K20: =undefined20+J14 -> #NAME? | L20: =undefined20+J15 -> #NAME? | M20: =undefined20+J16 -> #NAME?
A22: ="ARR run-rate fin Año 1 (COP): " & TEXT(D16*SUPUESTOS!B18*12,"#,##0") -> ARR run-rate fin Año 1 (COP): 256013748,0

Sheet 5 AÑOS
A1: BITAFLY — PROYECCIÓN 5 AÑOS
A3: Año | B3: Clientes (fin) | C3: ARPU mensual | D3: Ingreso anual | E3: Margen EBITDA | F3: EBITDA | G3: ARR run-rate | H3: Notas
A4: ↓ Crecimiento anual ARPU (% por año): | D4: 0.05
A5: ↓ Crecimiento clientes Año 2 (% sobre Año 1): | D5: 1.84
A6: ⚠ Años 2-5: ajusta manualmente clientes y margen EBITDA según tracción real. ARPU y ARR son fórmulas.
A8: Año 1 | B8: 148 | C8: =SUPUESTOS!B18 -> 229403 | D8: =B8*C8*12 -> 407419728 | E8: -0.17 | F8: =D8*E8 -> -69261354 | G8: =B8*C8*12 -> 407419728 | H8: Desde hoja AÑO 1
A9: Año 2 | B9: 420 | C9: =C8*(1+$D$4) -> 240873.15 | D9: =B9*C9*12 -> 1.2140007e+09 | E9: 0.1 | F9: =D9*E9 -> 1.2140007e+08 | G9: =B9*C9*12 -> 1.2140007e+09 | H9: ARPU +5% / año
A10: Año 3 | B10: 850 | C10: =C9*(1+$D$4) -> 252916.81 | D10: =B10*C10*12 -> 2.5797514e+09 | E10: 0.2 | F10: =D10*E10 -> 5.1595029e+08 | G10: =B10*C10*12 -> 2.5797514e+09
A11: Año 4 | B11: 1450 | C11: =C10*(1+$D$4) -> 265562.65 | D11: =B11*C11*12 -> 4.6207901e+09 | E11: 0.28 | F11: =D11*E11 -> 1.2938212e+09 | G11: =B11*C11*12 -> 4.6207901e+09
A12: Año 5 | B12: 2200 | C12: =C11*(1+$D$4) -> 278840.78 | D12: =B12*C12*12 -> 7.3613966e+09 | E12: 0.32 | F12: =D12*E12 -> 2.3556469e+09 | G12: =B12*C12*12 -> 7.3613966e+09
A15: ANÁLISIS DE SENSIBILIDAD — ARPU
A16: Escenario | B16: ARPU | C16: Ingreso Año 1 | D16: ARR Año 1
A17: Conservador (80% Piloto) | B17: 57200 | C17: =B17*148*12*0.7 -> 71111040 | D17: =B17*148*12 -> 101587200
A18: Base (60/25/12/3) | B18: 91900 | C18: =B18*148*12*0.7 -> 114250080 | D18: =B18*148*12 -> 163214400
A19: Optimista (+ Enterprise) | B19: 110000 | C19: =B19*148*12*0.7 -> 136752000 | D19: =B19*148*12 -> 195360000

Sheet VALORACIÓN
A1: BITAFLY — VALORACIÓN Y TABLA DE CAPITALIZACIÓN
A3: 1. VALORACIÓN PRE-MONEY
A4: Escenario | B4: Pre-money (COP) | C4: Pre-money (USD) | D4: Base de sustento
A5: Conservador | B5: 250000000 | C5: =B5/SUPUESTOS!B35 -> 65789.474 | D5: Anclado a costo de reposición
A6: Base (recomendado) | B6: 400000000 | C6: =B6/SUPUESTOS!B35 -> 105263.16 | D6: Producto + moat regulatorio + proyección
A7: Optimista | B7: 600000000 | C7: =B7/SUPUESTOS!B35 -> 157894.74 | D7: Con tracción temprana demostrada
A9: 2. VALOR POR ACCIÓN (total de 1.000 acciones)
A10: Escenario | B10: Pre-money (COP) | C10: Total acciones | D10: Precio por acción (COP) | E10: Precio por acción (USD)
A11: Total acciones base | B11: 1000
A12: Conservador | B12: =B5 -> 250000000 | C12: =B11 -> 1000 | D12: =B12/C12 -> 250000 | E12: =D12/SUPUESTOS!B35 -> 65.789474
A13: Base (recomendado) | B13: =B6 -> 400000000 | C13: =B11 -> 1000 | D13: =B13/C13 -> 400000 | E13: =D13/SUPUESTOS!B35 -> 105.26316
A14: Optimista | B14: =B7 -> 600000000 | C14: =B11 -> 1000 | D14: =B14/C14 -> 600000 | E14: =D14/SUPUESTOS!B35 -> 157.89474
A16: 3. ESCENARIOS DE RONDA (caso base pre-money $400M)
A17: Inversión (COP) | B17: Acciones nuevas | C17: % entregado | D17: Post-money (COP) | E17: Recomendado
A18: 120000000 | B18: =ROUND(A18/(B6/B11),0) -> 300 | C18: =B18/(B11+B18) -> 0.23076923 | D18: =B6+A18 -> 520000000
A19: 180000000 | B19: =ROUND(A19/(B6/B11),0) -> 450 | C19: =B19/(B11+B19) -> 0.31034483 | D19: =B6+A19 -> 580000000 | E19: ★ RECOMENDADO
A20: 260000000 | B20: =ROUND(A20/(B6/B11),0) -> 650 | C20: =B20/(B11+B20) -> 0.39393939 | D20: =B6+A20 -> 660000000
A23: 4. RETORNO PROYECTADO PARA EL INVERSIONISTA (caso base, $180M por 31%)
A24: Inversión entrada (COP) | B24: 180000000
A25: % participación | B25: 0.31
A26: Valoración Año 5 (ARR × 4×, COP) | B26: 11800000000
A27: Valor participación Año 5 (COP) | B27: =B24*B25 -> 55800000
A28: Retorno múltiplo (×) | B28: =B27/B24 -> 0.31
A29: TIR estimada (%) | B29: 0.82
